<?xml version="1.0"?>
<robot xmlns:xacro="http://www.ros.org/wiki/xacro">

  <xacro:macro name="diffbot" params="prefix">

    <!-- Constants for robot dimensions -->
    <xacro:property name="PI" value="3.1415926535897931"/>
    <xacro:property name="base_mass" value="3.4"/> <!-- arbitrary value for base mass -->
    <xacro:property name="base_width" value="0.24"/>
    <xacro:property name="base_length" value="0.13"/>
    <xacro:property name="base_length_collision" value="0.23"/>
    <xacro:property name="base_height" value="0.2"/>
    <xacro:property name="wheel_x_offset" value="0.0265"/>
    <xacro:property name="wheel_z_offset" value="0.1"/>
    <xacro:property name="wheel_separation" value="0.2"/>
    <xacro:property name="wheel_mass" value="0.3"/> <!-- arbitrary value for wheel mass -->
    <xacro:property name="wheel_len" value="0.030"/>
    <xacro:property name="wheel_radius" value="0.036"/>
    <xacro:property name="z_offset" value="-${base_height/2}"/> <!-- Space btw top of beam and the each joint -->

    <link name="base_footprint">
      <visual>
        <origin xyz="0 0 0" rpy="0 0 0"/>
        <geometry>
          <box size="0.01 0.01 0.005"/>
        </geometry>
        <material name="green"/>
      </visual>
    </link>

    <!-- Base Link -->
    <link name="${prefix}base_link">
      <visual>
        <origin xyz="0 0 0" rpy="0 0 0"/>
        <geometry>
          <box size="0.01 0.01 0.005"/>
        </geometry>
        <material name="blue"/>
      </visual>

      <inertial>
        <origin xyz="0 0 0" rpy="0 0 0"/>
        <mass value="${base_mass}"/>
        <inertia
          ixx="${base_mass / 12.0 * (base_length*base_length + base_height*base_height)}" ixy="0.0" ixz="0.0"
          iyy="${base_mass / 12.0 * (base_height*base_height + base_width*base_width)}" iyz="0.0"
          izz="${base_mass / 12.0 * (base_width*base_width + base_length*base_length)}"/>
      </inertial>

      <visual>
        <!--        TODO: was: -->
<!--        <origin xyz="0 0 ${base_height/2}" rpy="0 0 0"/>-->
        <origin xyz="0 0 0" rpy="0 0 0"/>
        <geometry>
          <box size="${base_width} ${base_length} ${base_height}"/>
        </geometry>
        <material name="orange"/>
      </visual>

      <collision>
        <origin xyz="0 0 0" rpy="0 0 0"/>
        <geometry>
          <box size="${base_width} ${base_length_collision} ${base_height}"/>
        </geometry>
      </collision>
    </link>

    <joint name="base_footprint_joint" type="fixed">
      <parent link="base_footprint"/>
      <child link="base_link"/>
      <origin xyz="0 0 ${base_height / 2 + wheel_radius}" rpy="0 0 0"/>
    </joint>

    <joint name="${prefix}left_wheel_joint" type="continuous">
      <parent link="${prefix}base_link"/>
      <child link="${prefix}left_wheel"/>
      <origin xyz="${wheel_x_offset} -${wheel_separation/2} -${wheel_z_offset}" rpy="0 0 0"/>
      <axis xyz="0 1 0"/>
      <dynamics damping="0.2"/>
      <limit effort="100" velocity="1.0"/>
    </joint>

    <!-- left wheel Link -->
    <link name="${prefix}left_wheel">
      <collision>
        <origin xyz="0 0 0" rpy="${PI/2} 0 0"/>
        <geometry>
          <cylinder length="${wheel_len}" radius="${wheel_radius}"/>
        </geometry>
      </collision>

      <visual>
        <origin xyz="0 0 0" rpy="${PI/2} 0 0"/>
        <geometry>
          <cylinder length="${wheel_len}" radius="${wheel_radius}"/>
        </geometry>
        <material name="black"/>
      </visual>

      <inertial>
        <origin xyz="0 0 0" rpy="${PI/2} 0 0"/>
        <mass value="${wheel_mass}"/>
        <inertia
          ixx="${wheel_mass / 12.0 * (3*wheel_radius*wheel_radius + wheel_len*wheel_len)}" ixy="0.0" ixz="0.0"
          iyy="${wheel_mass / 12.0 * (3*wheel_radius*wheel_radius + wheel_len*wheel_len)}" iyz="0.0"
          izz="${wheel_mass / 2.0 * wheel_radius*wheel_radius}"/>
      </inertial>
    </link>

    <joint name="${prefix}right_wheel_joint" type="continuous">
      <parent link="${prefix}base_link"/>
      <child link="${prefix}right_wheel"/>
      <origin xyz="${wheel_x_offset} ${wheel_separation/2} -${wheel_z_offset}" rpy="0 0 0"/>
      <axis xyz="0 1 0"/>
      <dynamics damping="0.2"/>
      <limit effort="100" velocity="1.0"/>
    </joint>

    <!-- right wheel Link -->
    <link name="${prefix}right_wheel">
      <collision>
        <origin xyz="0 0 0" rpy="${PI/2} 0 0"/>
        <geometry>
          <cylinder length="${wheel_len}" radius="${wheel_radius}"/>
        </geometry>
      </collision>

      <visual>
        <origin xyz="0 0 0" rpy="${PI/2} 0 0"/>
        <geometry>
          <cylinder length="${wheel_len}" radius="${wheel_radius}"/>
        </geometry>
        <material name="black"/>
      </visual>

      <inertial>
        <origin xyz="0 0 0" rpy="${PI/2} 0 0"/>
        <mass value="${wheel_mass}"/>
        <inertia
          ixx="${wheel_mass / 12.0 * (3*wheel_radius*wheel_radius + wheel_len*wheel_len)}" ixy="0.0" ixz="0.0"
          iyy="${wheel_mass / 12.0 * (3*wheel_radius*wheel_radius + wheel_len*wheel_len)}" iyz="0.0"
          izz="${wheel_mass / 2.0 * wheel_radius*wheel_radius}"/>
      </inertial>
    </link>

    <!-- ============================= -->
    <!-- Laser -->
    <!-- ============================= -->

    <link name="scan">
      <visual>
        <geometry>
          <cylinder radius="0.035" length="0.02"/>
        </geometry>
        <origin xyz="0 0 0" rpy="0 0 0"/>
        <material name="black"/>
      </visual>
    </link>

    <joint name="laser_joint" type="fixed">
      <parent link="base_link"/>
      <child link="scan"/>
      <origin xyz="-0.0725 0 0.11" rpy="0 0 0"/>
    </joint>

    <!-- ============================= -->
    <!-- Camera -->
    <!-- ============================= -->
    <link name="camera_link">
      <visual>
        <origin xyz="0 0 0" rpy="0 0 0"/>
        <geometry>
          <box size="0.03 ${base_length} 0.03"/>
        </geometry>
        <material name="black"/>
      </visual>
    </link>

    <joint name="camera_joint" type="fixed">
      <parent link="base_link"/>
      <child link="camera_link"/>
      <!-- Approximate front-top mount for the RealSense body. -->
      <origin xyz="0.105 0 0.085" rpy="0 0 0"/>
    </joint>

    <!-- ============================= -->
    <!-- IMU (future) -->
    <!-- ============================= -->

    <link name="imu_link">
      <visual>
        <origin xyz="0 0 0" rpy="0 0 0"/>
        <geometry>
          <box size="0.01 0.01 0.005"/>
        </geometry>
        <material name="red"/>
      </visual>
    </link>

    <joint name="imu_joint" type="fixed">
      <parent link="base_link"/>
      <child link="imu_link"/>
      <!--  TODO: validate     -->
      <origin xyz="0 0 -0.005" rpy="0 0 -${PI/2}"/>
    </joint>

  </xacro:macro>

</robot>
